2023-07-29 18:11:52,924 INFO    StreamThr :82413 [internal.py:wandb_internal():86] W&B internal server running at pid: 82413, started at: 2023-07-29 18:11:52.923846
2023-07-29 18:11:52,925 DEBUG   HandlerThread:82413 [handler.py:handle_request():144] handle_request: status
2023-07-29 18:11:52,933 INFO    WriterThread:82413 [datastore.py:open_for_write():85] open: /Users/vahid/GitHub/lc_qa_chat/wandb/run-20230729_181152-jvwix99t/run-jvwix99t.wandb
2023-07-29 18:11:52,933 DEBUG   SenderThread:82413 [sender.py:send():379] send: header
2023-07-29 18:11:52,955 DEBUG   SenderThread:82413 [sender.py:send():379] send: run
2023-07-29 18:11:53,234 ERROR   SenderThread:82413 [internal_api.py:execute():325] 404 response executing GraphQL.
2023-07-29 18:11:53,234 ERROR   SenderThread:82413 [internal_api.py:execute():326] {"errors":[{"message":"entity vahid-log not found during upsertBucket","path":["upsertBucket"]}],"data":{"upsertBucket":null}}
2023-07-29 18:11:53,235 ERROR   SenderThread:82413 [sender.py:send_run():976] It appears that you do not have permission to access the requested resource. Please reach out to the project owner to grant you access. If you have the correct permissions, verify that there are no issues with your networking setup.(Error 404: Not Found)
Traceback (most recent call last):
  File "/Users/vahid/GitHub/lc_qa_chat/venv/lib/python3.11/site-packages/wandb/sdk/lib/retry.py", line 131, in __call__
    result = self._call_fn(*args, **kwargs)
             ^^^^^^^^^^^^^^^^^^^^^^^^^^^^^^
  File "/Users/vahid/GitHub/lc_qa_chat/venv/lib/python3.11/site-packages/wandb/sdk/internal/internal_api.py", line 322, in execute
    return self.client.execute(*args, **kwargs)  # type: ignore
           ^^^^^^^^^^^^^^^^^^^^^^^^^^^^^^^^^^^^
  File "/Users/vahid/GitHub/lc_qa_chat/venv/lib/python3.11/site-packages/wandb/vendor/gql-0.2.0/wandb_gql/client.py", line 52, in execute
    result = self._get_result(document, *args, **kwargs)
             ^^^^^^^^^^^^^^^^^^^^^^^^^^^^^^^^^^^^^^^^^^^
  File "/Users/vahid/GitHub/lc_qa_chat/venv/lib/python3.11/site-packages/wandb/vendor/gql-0.2.0/wandb_gql/client.py", line 60, in _get_result
    return self.transport.execute(document, *args, **kwargs)
           ^^^^^^^^^^^^^^^^^^^^^^^^^^^^^^^^^^^^^^^^^^^^^^^^^
  File "/Users/vahid/GitHub/lc_qa_chat/venv/lib/python3.11/site-packages/wandb/sdk/lib/gql_request.py", line 56, in execute
    request.raise_for_status()
  File "/Users/vahid/GitHub/lc_qa_chat/venv/lib/python3.11/site-packages/requests/models.py", line 1021, in raise_for_status
    raise HTTPError(http_error_msg, response=self)
requests.exceptions.HTTPError: 404 Client Error: Not Found for url: https://api.wandb.ai/graphql

During handling of the above exception, another exception occurred:

Traceback (most recent call last):
  File "/Users/vahid/GitHub/lc_qa_chat/venv/lib/python3.11/site-packages/wandb/sdk/internal/sender.py", line 974, in send_run
    self._init_run(run, config_value_dict)
  File "/Users/vahid/GitHub/lc_qa_chat/venv/lib/python3.11/site-packages/wandb/sdk/internal/sender.py", line 1012, in _init_run
    server_run, inserted, server_messages = self._api.upsert_run(
                                            ^^^^^^^^^^^^^^^^^^^^^
  File "/Users/vahid/GitHub/lc_qa_chat/venv/lib/python3.11/site-packages/wandb/apis/normalize.py", line 73, in wrapper
    raise err
  File "/Users/vahid/GitHub/lc_qa_chat/venv/lib/python3.11/site-packages/wandb/apis/normalize.py", line 41, in wrapper
    return func(*args, **kwargs)
           ^^^^^^^^^^^^^^^^^^^^^
  File "/Users/vahid/GitHub/lc_qa_chat/venv/lib/python3.11/site-packages/wandb/sdk/internal/internal_api.py", line 1825, in upsert_run
    response = self.gql(
               ^^^^^^^^^
  File "/Users/vahid/GitHub/lc_qa_chat/venv/lib/python3.11/site-packages/wandb/sdk/internal/internal_api.py", line 294, in gql
    ret = self._retry_gql(
          ^^^^^^^^^^^^^^^^
  File "/Users/vahid/GitHub/lc_qa_chat/venv/lib/python3.11/site-packages/wandb/sdk/lib/retry.py", line 147, in __call__
    retry_timedelta_triggered = check_retry_fn(e)
                                ^^^^^^^^^^^^^^^^^
  File "/Users/vahid/GitHub/lc_qa_chat/venv/lib/python3.11/site-packages/wandb/util.py", line 946, in check_retry_fn
    return fallback_retry_fn(e)
           ^^^^^^^^^^^^^^^^^^^^
  File "/Users/vahid/GitHub/lc_qa_chat/venv/lib/python3.11/site-packages/wandb/util.py", line 888, in no_retry_auth
    raise CommError(
wandb.errors.CommError: It appears that you do not have permission to access the requested resource. Please reach out to the project owner to grant you access. If you have the correct permissions, verify that there are no issues with your networking setup.(Error 404: Not Found)
2023-07-29 18:11:53,340 DEBUG   HandlerThread:82413 [handler.py:handle_request():144] handle_request: shutdown
2023-07-29 18:11:53,340 INFO    HandlerThread:82413 [handler.py:finish():857] shutting down handler
2023-07-29 18:11:53,960 INFO    WriterThread:82413 [datastore.py:close():294] close: /Users/vahid/GitHub/lc_qa_chat/wandb/run-20230729_181152-jvwix99t/run-jvwix99t.wandb
2023-07-29 18:11:54,246 INFO    SenderThread:82413 [sender.py:finish():1552] shutting down sender
